<?xml version="1.0" encoding="utf-8"?>
<robot name="ABB_IRB4400L_30_243" payload="30" reach="2.43" brand="ABB" type="Robot">
  <material name="abb_black">
    <color rgba="0.1882353 0.1960784 0.2039216 1"/>
  </material>
  <material name="abb_orange">
    <color rgba="0.7372549 0.3490196 0.1607843 1"/>
  </material>
  <material name="abb_yellow">
    <color rgba="1 1 0 1"/>
  </material>
  <!-- link list -->
  <link name="base_link">
    <visual>
      <origin xyz="0 0 0" rpy="0 0 0"/>
      <geometry>
        <mesh filename="visual/base_link.stl"/>
      </geometry>
      <material name="abb_orange"/>
    </visual>
    <collision>
      <geometry>
        <mesh filename="collision/base_link.stl"/>
      </geometry>
      <material name="abb_yellow"/>
    </collision>
  </link>
  <link name="link_1">
    <visual>
      <origin xyz="0 0 0" rpy="0 0 0"/>
      <geometry>
        <mesh filename="visual/link_1.stl"/>
      </geometry>
      <material name="abb_orange"/>
    </visual>
    <collision>
      <origin xyz="0 0 0" rpy="0 0 0"/>
      <geometry>
        <mesh filename="collision/link_1.stl"/>
      </geometry>
      <material name="abb_yellow"/>
    </collision>
  </link>
  <link name="link_2">
    <visual>
      <origin xyz="0 0 0" rpy="0 0 0"/>
      <geometry>
        <mesh filename="visual/link_2.stl"/>
      </geometry>
      <material name="abb_orange"/>
    </visual>
    <collision>
      <origin xyz="0 0 0" rpy="0 0 0"/>
      <geometry>
        <mesh filename="collision/link_2.stl"/>
      </geometry>
      <material name="abb_yellow"/>
    </collision>
  </link>
  <link name="link_3">
    <visual>
      <origin xyz="0 0 0" rpy="0 0 0"/>
      <geometry>
        <mesh filename="visual/link_3.stl"/>
      </geometry>
      <material name="abb_orange"/>
    </visual>
    <collision>
      <origin xyz="0 0 0" rpy="0 0 0"/>
      <geometry>
        <mesh filename="collision/link_3.stl"/>
      </geometry>
      <material name="abb_yellow"/>
    </collision>
  </link>
  <link name="link_4">
    <visual>
      <origin xyz="0 0 0" rpy="0 0 0"/>
      <geometry>
        <mesh filename="visual/link_4.stl"/>
      </geometry>
      <material name="abb_orange"/>
    </visual>
    <collision>
      <origin xyz="0 0 0" rpy="0 0 0"/>
      <geometry>
        <mesh filename="collision/link_4.stl"/>
      </geometry>
      <material name="abb_yellow"/>
    </collision>
  </link>
  <link name="link_5">
    <visual>
      <origin xyz="0 0 0" rpy="0 0 0"/>
      <geometry>
        <mesh filename="visual/link_5.stl"/>
      </geometry>
      <material name="abb_orange"/>
    </visual>
    <collision>
      <origin xyz="0 0 0" rpy="0 0 0"/>
      <geometry>
        <mesh filename="collision/link_5.stl"/>
      </geometry>
      <material name="abb_yellow"/>
    </collision>
  </link>
  <link name="link_6">
    <visual>
      <origin xyz="0 0 0" rpy="0 0 0"/>
      <geometry>
        <mesh filename="visual/link_6.stl"/>
      </geometry>
      <material name="abb_black"/>
    </visual>
    <collision>
      <origin xyz="0 0 0" rpy="0 0 0"/>
      <geometry>
        <mesh filename="collision/link_6.stl"/>
      </geometry>
      <material name="abb_yellow"/>
    </collision>
  </link>
  <link name="tool0"/>
  <!-- end of link list -->
  <!-- joint list -->
  <joint name="joint_1" type="revolute">
    <origin xyz="0 0 0" rpy="0 0 0"/>
    <parent link="base_link"/>
    <child link="link_1"/>
    <axis xyz="0 0 1"/>
    <limit effort="0" lower="-2.87979" upper="2.87979" velocity="2.618"/>
  </joint>
  <joint name="joint_2" type="revolute">
    <origin xyz="0.2 0 0.68" rpy="0 0 0"/>
    <parent link="link_1"/>
    <child link="link_2"/>
    <axis xyz="0 1 0"/>
    <limit effort="0" lower="-1.2217" upper="1.658" velocity="2.0944"/>
  </joint>
  <joint name="joint_3" type="revolute">
    <origin xyz="0 0 0.89" rpy="0 0 0"/>
    <parent link="link_2"/>
    <child link="link_3"/>
    <axis xyz="0 1 0"/>
    <limit effort="0" lower="-1.0472" upper="1.1345" velocity="2.0944"/>
  </joint>
  <joint name="joint_4" type="revolute">
    <origin xyz="1.38 0 0.15" rpy="0 0 0"/>
    <parent link="link_3"/>
    <child link="link_4"/>
    <axis xyz="1 0 0"/>
    <limit effort="0" lower="-3.49" upper="3.49" velocity="3.927"/>
  </joint>
  <joint name="joint_5" type="revolute">
    <origin xyz="0 0 0" rpy="0 0 0"/>
    <parent link="link_4"/>
    <child link="link_5"/>
    <axis xyz="0 1 0"/>
    <limit effort="0" lower="-2.0944" upper="2.0944" velocity="4.3633"/>
  </joint>
  <joint name="joint_6" type="revolute">
    <origin xyz="0 0 0" rpy="0 0 0"/>
    <parent link="link_5"/>
    <child link="link_6"/>
    <axis xyz="1 0 0"/>
    <limit effort="0" lower="-6.9813" upper="6.9813" velocity="5.7596"/>
  </joint>
  <joint name="joint_6-tool0" type="fixed">
    <parent link="link_6"/>
    <child link="tool0"/>
    <origin xyz="0.14 0 0" rpy="0 0 0"/>
  </joint>
  <!-- end of joint list -->
  <!-- ROS base_link to ABB World Coordinates transform -->
  <link name="base"/>
  <joint name="base_link-base" type="fixed">
    <origin xyz="0 0 0" rpy="0 0 0"/>
    <parent link="base_link"/>
    <child link="base"/>
  </joint>
</robot>
