<?xml version="1.0" encoding="utf-8"?>
<robot name="KUKA_KR6R900_2" payload="6" reach="0.901" brand="KUKA" type="Robot">
  <material name="kuka_black">
    <color rgba="0.054902 0.054902 0.062745 1.0"/>
  </material>
  <material name="kuka_ral_gray_aluminium">
    <color rgba="0.529412 0.521569 0.505882 1.0"/>
  </material>
  <material name="kuka_ral_traffic_white">
    <color rgba="0.945098  0.941176 0.917647 1.0"/>
  </material>
  <link name="base_link">
    <visual>
      <origin xyz="0 0 0" rpy="0 0 0"/>
      <geometry>
        <mesh filename="visual/base_link.stl"/>
      </geometry>
      <material name="kuka_ral_gray_aluminium"/>
    </visual>
    <collision>
      <origin xyz="0 0 0" rpy="0 0 0"/>
      <geometry>
        <mesh filename="collision/base_link.stl"/>
      </geometry>
    </collision>
  </link>
  <link name="link_1">
    <visual>
      <origin xyz="0 0 0" rpy="0 0 0"/>
      <geometry>
        <mesh filename="visual/link_1.stl"/>
      </geometry>
      <material name="kuka_ral_traffic_white"/>
    </visual>
    <collision>
      <origin xyz="0 0 0" rpy="0 0 0"/>
      <geometry>
        <mesh filename="collision/link_1.stl"/>
      </geometry>
    </collision>
  </link>
  <link name="link_2">
    <visual>
      <origin xyz="0 0 0" rpy="0 0 0"/>
      <geometry>
        <mesh filename="visual/link_2.stl"/>
      </geometry>
      <material name="kuka_ral_traffic_white"/>
    </visual>
    <collision>
      <origin xyz="0 0 0" rpy="0 0 0"/>
      <geometry>
        <mesh filename="collision/link_2.stl"/>
      </geometry>
    </collision>
  </link>
  <link name="link_3">
    <visual>
      <origin xyz="0 0 0" rpy="0 0 0"/>
      <geometry>
        <mesh filename="visual/link_3.stl"/>
      </geometry>
      <material name="kuka_ral_traffic_white"/>
    </visual>
    <collision>
      <origin xyz="0 0 0" rpy="0 0 0"/>
      <geometry>
        <mesh filename="collision/link_3.stl"/>
      </geometry>
    </collision>
  </link>
  <link name="link_4">
    <visual>
      <origin xyz="0 0 0" rpy="0 0 0"/>
      <geometry>
        <mesh filename="visual/link_4.stl"/>
      </geometry>
      <material name="kuka_ral_traffic_white"/>
    </visual>
    <collision>
      <origin xyz="0 0 0" rpy="0 0 0"/>
      <geometry>
        <mesh filename="collision/link_4.stl"/>
      </geometry>
    </collision>
  </link>
  <link name="link_5">
    <visual>
      <origin xyz="0 0 0" rpy="0 0 0"/>
      <geometry>
        <mesh filename="visual/link_5.stl"/>
      </geometry>
      <material name="kuka_ral_traffic_white"/>
    </visual>
    <collision>
      <origin xyz="0 0 0" rpy="0 0 0"/>
      <geometry>
        <mesh filename="collision/link_5.stl"/>
      </geometry>
    </collision>
  </link>
  <link name="link_6">
    <visual>
      <origin xyz="0 0 0" rpy="0 0 0"/>
      <geometry>
        <mesh filename="visual/link_6.stl"/>
      </geometry>
      <material name="kuka_black"/>
    </visual>
    <collision>
      <origin xyz="0 0 0" rpy="0 0 0"/>
      <geometry>
        <mesh filename="collision/link_6.stl"/>
      </geometry>
    </collision>
  </link>
  <joint name="joint_a1" type="revolute">
    <origin xyz="0 0 0.400" rpy="0 0 0"/>
    <parent link="base_link"/>
    <child link="link_1"/>
    <axis xyz="0 0 -1"/>
    <limit effort="0" lower="${radians(-170)}" upper="${radians(170)}" velocity="${radians(360)}"/>
  </joint>
  <joint name="joint_a2" type="revolute">
    <origin xyz="0.025 0 0" rpy="0 0 0"/>
    <parent link="link_1"/>
    <child link="link_2"/>
    <axis xyz="0 1 0"/>
    <limit effort="0" lower="${radians(-190)}" upper="${radians(45)}" velocity="${radians(300)}"/>
  </joint>
  <joint name="joint_a3" type="revolute">
    <origin xyz="0.455 0 0" rpy="0 0 0"/>
    <parent link="link_2"/>
    <child link="link_3"/>
    <axis xyz="0 1 0"/>
    <limit effort="0" lower="${radians(-120)}" upper="${radians(156)}" velocity="${radians(360)}"/>
  </joint>
  <joint name="joint_a4" type="revolute">
    <origin xyz="0 0 0.025" rpy="0 0 0"/>
    <parent link="link_3"/>
    <child link="link_4"/>
    <axis xyz="-1 0 0"/>
    <limit effort="0" lower="${radians(-185)}" upper="${radians(185)}" velocity="${radians(450)}"/>
  </joint>
  <joint name="joint_a5" type="revolute">
    <origin xyz="0.420 0 0" rpy="0 0 0"/>
    <parent link="link_4"/>
    <child link="link_5"/>
    <axis xyz="0 1 0"/>
    <limit effort="0" lower="${radians(-120)}" upper="${radians(120)}" velocity="${radians(450)}"/>
  </joint>
  <joint name="joint_a6" type="revolute">
    <origin xyz="0.090 0 0" rpy="0 0 0"/>
    <parent link="link_5"/>
    <child link="link_6"/>
    <axis xyz="-1 0 0"/>
    <limit effort="0" lower="${radians(-350)}" upper="${radians(350)}" velocity="${radians(540)}"/>
  </joint>
  <!-- ROS-Industrial 'base' frame: base_link to KUKA $ROBROOT coordinate system transform -->
  <link name="base"/>
  <joint name="base_link-base" type="fixed">
    <origin xyz="0 0 0" rpy="0 0 0"/>
    <parent link="base_link"/>
    <child link="base"/>
  </joint>
  <!-- ROS-Industrial 'flange' frame: attachment point for EEF models -->
  <link name="flange"/>
  <joint name="joint_6-flange" type="fixed">
    <origin xyz="0 0 0" rpy="0 0 0"/>
    <parent link="link_6"/>
    <child link="flange"/>
  </joint>
  <!-- ROS-Industrial 'tool0' frame: all-zeros tool frame -->
  <!-- This frame corresponds to the $FLANGE coordinate system in KUKA KRC controllers. -->
  <link name="tool0"/>
  <joint name="flange-tool0" type="fixed">
    <parent link="flange"/>
    <child link="tool0"/>
    <origin xyz="0 0 0" rpy="0 ${radians(90)} 0"/>
  </joint>
</robot>
